Workbook

Sheet Planter Layout
C2: WALL
B3: Pepperoncini | C3: Rosemary | D3: Cucumber | E3: Okra
B4: Tomato Beefsteak | C4: Tomato Roma | D4: Jalapeno | E4: Okra
C5: Ground Cherry | D5: Broccoli | E5: Broccoli
C6: Fennel | D6: Broccoli | E6: Broccoli
C7: Fennel | D7: Watermelon | E7: Watermelon
C8: Fennel | D8: Fennel | E8: Common Mullein

Sheet Seed Inventory
B1: Label | C1: Seed | D1: Date | E1: Label | F1: Seed | G1: Date
B2: A | C2: Anaheim Hot Pepper, Heirloom | D2: 2023 | E2: JJ | F2: Cape Gooseberries | G2: 2024
B3: B | C3: Early Jalapeno, Heirloom | D3: 2023 | E3: KK | F3: Dill | G3: 2024
B4: C | C4: Lavender | D4: 2023 | E4: LL | F4: Saskatoon Serviceberry | G4: 2024
B5: D | C5: Italian Pepperoncini Hot Pepper | D5: 2023 | E5: MM | F5: Round Zucchini | G5: 2024
B6: E | C6: Snow Pea, Heirloom | D6: 2023 | E6: NN | F6: Golden Zucchini | G6: 2024
B7: F | C7: Cucumber, Pick-a-bushel Hybrid | D7: 2023 | E7: OO | F7: Grey Zucchini | G7: 2024
B8: G | C8: Tomato, Black Cherry, Heirloom | D8: 2023 | E8: PP | F8: Cocozelle Zucchini | G8: 2024
B9: H | C9: Radish, Daikon Minowase, Heirloom | D9: 2023 | E9: QQ | F9: Zucchini Black Beauty | G9: 2024
B10: I | C10: Okra, Clemson Spineless, Heirloom | D10: 2023 | E10: RR | F10: Summer Squash 49er Hybrid | G10: 2024
B11: J | C11: Tomato, Mortgage Lifter, Heirloom | D11: 2023 | E11: SS | F11: Lemon Balm | G11: 2024
B12: K | C12: Carrot, Nates Half Long | D12: 2023 | E12: TT | F12: Caulifower | G12: 2024
B13: L | C13: Thyme | D13: 2022 | E13: UU | F13: Strawberries (wild) | G13: 2025
B14: M | C14: Oregano, Greek | D14: 2022 | E14: A1 | F14: Tomatillo (Toma Verde) | G14: 2025
B15: N | C15: Cucumber, Sumpter | D15: 2022 | E15: A2 | F15: Cayenne Long Slim Hot Pepper | G15: 2025
B16: O | C16: Tomato, Beefsteak | D16: 2022 | E16: A3 | F16: Sweet Banana Pepper | G16: 2025
B17: P | C17: Jalapeno, Heirloom | D17: 2022 | E17: A4 | F17: Hot Banana Pepper | G17: 2025
B18: Q | C18: Bok Choy, White Stem, Heirloom | D18: 2022 | E18: A5 | F18: Eggplant | G18: 2025
B19: R | C19: Sage, Broad Leaf | D19: 2022 | E19: A6 | F19: Calendula (greenheart mix) | G19: 2025
B20: S | C20: Okra, Emerald | D20: 2023 | E20: A7 | F20: Assorted Pepper Seeds | G20: 2024
B21: T | C21: Pole Bean, Kentucky Wonder, Heirloom | D21: 2023 | E21: A8 | F21: Marigold (crackerjack) | G21: 2025
B22: U | C22: Broccoli, De Cicco, Heirloom | D22: 2023 | E22: A9 | F22: Kabocha Squash | G22: 2025
B23: V | C23: Tomato, Roma | D23: 2023 | E23: B1 | F23: Butternut Squash | G23: 2025
B24: W | C24: Basil, Sweet Italian | D24: 2025 | E24: B2 | F24: Italian Parsley | G24: 2025
... B28: AA | C28: Rosemary | D28: 2023 | E28: B6 | F28: Curled Chervil | G28: 2025
B29: BB | C29: Spinach | D29: 2022 | E29: B7 | F29: Chives
B30: CC | C30: Fennel | D30: 2023
B31: DD | C31: Asparagus | D31: 2023 | F31: mid-late February
B32: EE | C32: Chamomile | D32: 2023 | F32: mid-late March
B33: FF | C33: Watermelon, Sugar Baby, Herloom | D33: 2023 | F33: Late April
B34: GG | C34: Green Pepper | D34: 2023 | F34: Late September
B35: HH | C35: Common Mullein | D35: 2023
B36: II | C36: Sweet Corn | D36: 2024

Sheet Calendar
C1: January | F1: February | I1: March | L1: April | O1: May | R1: June | U1: July | X1: August | AA1: September | AD1: October | AG1: November | AJ1: December
A2: ='Seed Inventory'!C4 -> Lavender | B2: Plant Indoors
B3: Sow
B4: Harvest
A5: ='Seed Inventory'!C8 -> Tomato, Black Cherry, Heirloom | B5: Plant Indoors
B6: Sow
B7: Harvest
A8: ='Seed Inventory'!C3 -> Early Jalapeno, Heirloom | B8: Plant Indoors
B9: Sow
B10: Harvest
A11: ='Seed Inventory'!C5 -> Italian Pepperoncini Hot Pepper | B11: Plant Indoors
B12: Sow
B13: Harvest
A14: ='Seed Inventory'!C2 -> Anaheim Hot Pepper, Heirloom | B14: Plant Indoors
B15: Sow
B16: Harvest
A17: ='Seed Inventory'!C23 -> Tomato, Roma | B17: Plant Indoors
B18: Sow
B19: Harvest
A20: ='Seed Inventory'!C11 -> Tomato, Mortgage Lifter, Heirloom | B20: Plant Indoors
B21: Sow
B22: Harvest
A23: ='Seed Inventory'!C7 -> Cucumber, Pick-a-bushel Hybrid | B23: Plant Indoors
B24: Sow
B25: Harvest
A26: ='Seed Inventory'!C6 -> Snow Pea, Heirloom | B26: Plant Indoors
B27: Sow
B28: Harvest
A29: ='Seed Inventory'!C21 -> Pole Bean, Kentucky Wonder, Heirloom | B29: Plant Indoors
B30: Sow
B31: Harvest
A32: ='Seed Inventory'!C22 -> Broccoli, De Cicco, Heirloom | B32: Plant Indoors
B33: Sow
B34: Harvest
A35: Sunflower | B35: Plant Indoors
B36: Sow
B37: Harvest
A38: ='Seed Inventory'!C26 -> Leek, King Richard | B38: Plant Indoors
B39: Sow
B40: Harvest
...

Sheet Garden Layout
K3: House
K8: Sweet Corn Cocozelle Zuks | L8: Sweet Corn Cocozelle Zuks | M8: Sweet Corn Grey Zuks | N8: Sweet Corn Grey Zuks | O8: Sweet Corn Round Zuks | P8: Sweet Corn Round Zuks | Q8: Sweet Corn Golden Zuks | R8: Sweet Corn Golden Zuks | S8: Patio
K11: Silver Queen Corn Cocozelle Zuks | L11: Silver Queen Corn Cocozelle Zuks | M11: Silver Queen Corn Grey Zuks | N11: Silver Queen Corn Grey Zuks | O11: Silver Queen Corn Round Zuks | P11: Silver Queen Corn Round Zuks | Q11: Silver Queen Corn Golden Zuks | R11: Silver Queen Corn Golden Zuks
M20: House | O20: Composter | P20: Round Zukes
O26: Composter
M32: Deck | O32: Corn Summer Squash | P32: Corn Summer Squash
O35: Corn Golden Zuks | P35: Corn Golden Zuks
O38: Corn Black Beauty Zuks | P38: Corn Black Beauty Zuks

Sheet Planting Schedule
A1: Plant Label | B1: Quantity | C1: Days to Sprout | D1: Days to Maturity | E1: Plant Indoors | F1: Sow Indoors | G1: Sow/Plant Outdoors | H1: Harvest
A2: ='Seed Inventory'!C4 -> Lavender | B2: 6 | D2: 85 | E2: Yes | F2: 44972 | G2: 45017 | H2: =Table1[[#This Row],[Sow/Plant Outdoors]]+Table1[[#This Row],[Days to Maturity]] -> 45102
A3: ='Seed Inventory'!C8 -> Tomato, Black Cherry, Heirloom | B3: 1 | C3: 14 | D3: 70 | E3: Yes | F3: 44972 | G3: 45047 | H3: =Table1[[#This Row],[Sow/Plant Outdoors]]+Table1[[#This Row],[Days to Maturity]] -> 45117
A4: ='Seed Inventory'!C3 -> Early Jalapeno, Heirloom | B4: 1 | C4: 20 | D4: 45 | E4: Yes | F4: 44972 | G4: 45078 | H4: =Table1[[#This Row],[Sow/Plant Outdoors]]+Table1[[#This Row],[Days to Maturity]] -> 45123
A5: ='Seed Inventory'!C5 -> Italian Pepperoncini Hot Pepper | B5: 2 | C5: 20 | D5: 45 | E5: Yes | F5: 44972 | G5: 45078 | H5: =Table1[[#This Row],[Sow/Plant Outdoors]]+Table1[[#This Row],[Days to Maturity]] -> 45123
A6: ='Seed Inventory'!C2 -> Anaheim Hot Pepper, Heirloom | B6: 1 | C6: 25 | D6: 45 | E6: Yes | F6: 44972 | G6: 45078 | H6: =Table1[[#This Row],[Sow/Plant Outdoors]]+Table1[[#This Row],[Days to Maturity]] -> 45123
A7: ='Seed Inventory'!C23 -> Tomato, Roma | B7: 1 | D7: 78 | F7: 44986 | G7: 45031 | H7: =Table1[[#This Row],[Sow/Plant Outdoors]]+Table1[[#This Row],[Days to Maturity]] -> 45109
A8: ='Seed Inventory'!C11 -> Tomato, Mortgage Lifter, Heirloom | B8: 1 | D8: 85 | F8: 44986 | G8: 45031 | H8: =Table1[[#This Row],[Sow/Plant Outdoors]]+Table1[[#This Row],[Days to Maturity]] -> 45116
A9: ='Seed Inventory'!C7 -> Cucumber, Pick-a-bushel Hybrid | B9: 2 | C9: 14 | D9: 50 | E9: Yes | F9: 45017 | G9: 45047 | H9: =Table1[[#This Row],[Sow/Plant Outdoors]]+Table1[[#This Row],[Days to Maturity]] -> 45097
A10: ='Seed Inventory'!C6 -> Snow Pea, Heirloom | B10: 11 | C10: 14 | D10: 68 | E10: Yes | F10: =Table1[[#This Row],[Sow/Plant Outdoors]]-14 -> 45017 | G10: 45031 | H10: =Table1[[#This Row],[Sow/Plant Outdoors]]+Table1[[#This Row],[Days to Maturity]] -> 45099
A11: ='Seed Inventory'!C21 -> Pole Bean, Kentucky Wonder, Heirloom | B11: 8 | H11: =Table1[[#This Row],[Sow/Plant Outdoors]]+Table1[[#This Row],[Days to Maturity]] -> 0
A12: ='Seed Inventory'!C22 -> Broccoli, De Cicco, Heirloom | B12: 2 | H12: =Table1[[#This Row],[Sow/Plant Outdoors]]+Table1[[#This Row],[Days to Maturity]] -> 0
A13: Sunflower | B13: 4 | H13: =Table1[[#This Row],[Sow/Plant Outdoors]]+Table1[[#This Row],[Days to Maturity]] -> 0
A14: ='Seed Inventory'!C26 -> Leek, King Richard | B14: 7 | D14: 75 | E14: No | G14: 45000 | H14: =Table1[[#This Row],[Sow/Plant Outdoors]]+Table1[[#This Row],[Days to Maturity]] -> 45075
A15: ='Seed Inventory'!C9 -> Radish, Daikon Minowase, Heirloom | B15: 32 | C15: 10 | D15: 45 | E15: No | G15: 45000 | H15: 45078
A16: ='Seed Inventory'!C10 -> Okra, Clemson Spineless, Heirloom | B16: 5 | C16: 10 | D16: 65 | E16: No | G16: 45061 | H16: =Table1[[#This Row],[Sow/Plant Outdoors]]+Table1[[#This Row],[Days to Maturity]] -> 45126
A17: Chinese Wine Berries | H17: August - September
A18: Black Berries | H18: July - August
A19: Rasberries | H19: July - August
A20: Dandilion | H20: June - September
A21: Blue Berries | H21: May - August
A22: Black Walnuts | H22: September - November
A23: Acrons | H23: September - October

Sheet Food Prep Schedule
C1: January | D1: February | E1: March | F1: April | G1: May | H1: June | I1: July | J1: August | K1: September | L1: October | M1: November
C2: Syrup: https://practicalselfreliance.com/trees-species-tap-syrup/ | E2: Garlic Mustard Pesto: https://backyardforager.com/garlic-mustard-pesto/ | F2: Pickled Asparagus: https://www.allrecipes.com/recipe/69722/pickled-asparagus/ | G2: Blueberry preserves | H2: Korean Radish http://www.kimchichick.com/pickled-korean-radish/ | I2: Ground cherry recipes https://www.smithsonianmag.com/arts-culture/five-ways-to-eat-ground-cherries-98470003/
E3: Japanese Knotweed Jam (use it like rhubarb): https://www.delish.com/cooking/recipe-ideas/a27059524/rhubarb-jam-recipe/ | G3: Fermented Kimchi: https://www.thekitchn.com/how-to-make-easy-kimchi-at-home-189390 | H3: Chicken noodle soup with Radish | I3: Pickle jalapeno, pepperoncini and anaheim
H4: Preserve Radishes - Dehydrate radishes. They will rehydrate in soup - Freeze radishes https://www.thepurposefulpantry.com/preserve-radishes/ | I4: marinara sauce
H5: Preserve Leeks https://www.homestratosphere.com/store-leeks/ | I5: can tomatoes https://www.allrecipes.com/article/how-to-can-tomatoes/
H6: Freeze brocolli | I6: Tomato paste https://www.thespruceeats.com/easy-homemade-tomato-paste-recipe-2216043
H7: Pickle cucumbers | I7: tomato soup with grilled cheese
H8: Freeze snow peas | I8: Preserve tomatos: https://www.thespruceeats.com/how-to-preserve-tomatoes-2217665
H9: Freeze pole beans | I9: Other tomato recipes: https://www.allrecipes.com/recipes/1095/fruits-and-vegetables/vegetables/tomatoes/
H10: Dandelion salad
H11: Mulberry preserves
H12: Mulberry pie https://www.yummly.com/recipe/Mulberry-Pie-Allrecipes?prm-v1

Sheet Fermentation
A23: lbs of Veges | B23: Amount of salt (tsp) | C23: Additional water (cups) | D23: Additional salt (tsp)
A24: 0.25 | B24: 0.5 | C24: 0.5 | D24: 0.4
A25: 0.5 | B25: =B24+0.5 -> 1 | C25: =C24+0.5 -> 1 | D25: =D24+0.4 -> 0.8
A26: 0.75 | B26: =B25+0.5 -> 1.5 | C26: =C25+0.5 -> 1.5 | D26: =D25+0.4 -> 1.2
A27: 1 | B27: =B26+0.5 -> 2 | C27: =C26+0.5 -> 2 | D27: =D26+0.4 -> 1.6
A28: 1.25 | B28: =B27+0.5 -> 2.5 | C28: =C27+0.5 -> 2.5 | D28: =D27+0.4 -> 2
A29: 1.5 | B29: =B28+0.5 -> 3 | C29: =C28+0.5 -> 3 | D29: =D28+0.4 -> 2.4
A30: 1.75 | B30: =B29+0.5 -> 3.5 | C30: =C29+0.5 -> 3.5 | D30: =D29+0.4 -> 2.8
A31: 2 | B31: =B30+0.5 -> 4 | C31: =C30+0.5 -> 4 | D31: =D30+0.4 -> 3.2
A32: 2.25 | B32: =B31+0.5 -> 4.5 | C32: =C31+0.5 -> 4.5 | D32: =D31+0.4 -> 3.6
A33: 2.5 | B33: =B32+0.5 -> 5 | C33: =C32+0.5 -> 5 | D33: =D32+0.4 -> 4
A34: 2.75 | B34: =B33+0.5 -> 5.5 | C34: =C33+0.5 -> 5.5 | D34: =D33+0.4 -> 4.4
A35: 3 | B35: =B34+0.5 -> 6 | C35: =C34+0.5 -> 6 | D35: =D34+0.4 -> 4.8
A36: 3.25 | B36: =B35+0.5 -> 6.5 | C36: =C35+0.5 -> 6.5 | D36: =D35+0.4 -> 5.2
... A39: 4 | B39: =B38+0.5 -> 8 | C39: =C38+0.5 -> 8 | D39: =D38+0.4 -> 6.4
A41: Pickle ingredients: dill + 1/4 white vinegar + mustard seed + coriander seed + black peppercorn dried garlic red pepper flakes + Celery Seed

Sheet Planting and Harvesting
A1: Plant Type | B1: What Goes In The Ground? (Seed, Stem or Tuber) | C1: Planting Technique | D1: Grow Period and Maintenance | E1: Harvest Technique | F1: Preservation/curing
A2: Potato | B2: Spud - cut with eyes or a whole spud Tip: Buy bunching varieties rather than vine so that you don't have to hunt for potatoes | C2: Plant 6-12" below the surface. Best to make a mound for easier harvest so that the ground is loose. Tip: mulch with a mound of leaves | D2: all summer, very low maintenance. | E2: wait for the plant to die. Then wait an extra 2 weeks before harvest
A3: Sunchokes | B3: whole tuber | C3: do not cut the tuber. Best to plant in a container due to invasiveness | D3: no maintenace all summer. Cut off the flowers at the end of the season to trigger tuber development | E3: Leave in the ground through winter and harvest as needed
A4: Winter Squash | B4: seed | C4: 1" below the surface in an area with moist soil and full sun Tip: trellis this plant so that you can go vertical and so you can keep track of where the squash are | D4: all summer, very low maintenance | E4: Let the squash ripen to the point where there is no green left on the squash or veins. Then leave out in the sun for a few days to cure
A5: jalapenos | B5: seed | C5: plant them somewhere they can get heat and sun
A6: Corn | B6: Seed | C6: Plant in at least three rows 12" wide, with each kernel a couple of inches apart tip: planting in a square block works better than a row because corn is wind polinated
A7: tomatoes | B7: seed
A8: Carots | B8: Seed | C8: plant really early in the spring and plant them thick so you can thin them out later tip: find a short stumpy rather than long skinny ones | D8: thin out the carrots to about as wide as you want them to be (3-4 in) | E8: pull them up from the leaves. Will store for a quite a while
A9: Stawberries | B9: Seed | C9: plant in rows and cover with straw | D9: Keep straw down year round. Don't let them grow into a patch unless you want them for ground cover | E9: Harvest frequently. To keep the strawberries from going rotten. Consider planting new strawberries every year to keep them big. They will get smaller every year otherwise
A10: Cilantro | B10: seed | D10: harvest routinely to keep them from bolting | E10: leave about 1/3 of the plants to go to seed. They will reseed themselves
A11: Onion | B11: seed | C11: plant in a row 6" apart. They don't want to be crowded in the ground or fight for sunlight | D11: water and weed. Mulch with leaves | E11: once the tops have flopped over for at least a week, they are ready to harvest | F11: let sit outside in covered daylight (i.e. under the patio cover) for 1-2 weeks. Once the tops have browned, cut off leaving about 2" above the onion. Then let them sit in the same place for another 2 weeks
A12: beans/peas | B12: q | C12: beans like company so put two in each hole | D12: train on a trellis | E12: Wait for the vines to be dead and dry. Pull all the vines onto the patio and pick all the pods while comfortable on the porch. Then put the pods into a pillow case and beat it to release the beans | F12: put into a mason jar

Sheet Pest Control
A1: Plants you're Trying to Protect | B1: Technique | C1: Pest
A2: Cucumbers, Squash Melons and Cabbage and watermelon | B2: Plant Radishes as a trap plant | C2: Flea Beatles and Root Maggots
A3: Tomatoes, beans, peppers, melons | C3: Aphids and nematodes
A4: tomatoes, potatoes and beans | B4: Plant mustard as a trap plant | C4: Flea Beatles and aphids
A5: Tomatoes | B5: plant dill as a trap plant. It attracks horn worms, but the horn worms don't damage the plan | C5: horn worms
A6: Tomatoes and strawberries | B6: plant borage as a trap plant | C6: horn worms
